Workbook

Sheet OVERVIEW
A1: FMI V2
E2: MASTER QC-A REPORT | O2: FAIL
B5: PRODUCTION COMPANY | L5: QC # | O5: 303288
B6: TITLE | L6: PASS/FAIL | O6: =O2 -> FAIL
B7: EPISODE | L7: DATE | O7: =O63 -> 45403
B8: ELEMENT | L8: QC Operator
B9: FILE NAME | L9: PAGE | O9: 1/5
E10: ELEMENT & TECHNICAL INFORMATION
B12: TITLE | L12: CONTAINER/FORMAT
B13: EPISODE NAME | L13: CODEC
B14: EPISODE NUMBER | L14: RESOLUTION
B15: VERSION | E15: UHD SDR | L15: FRAME RATE
B16: TRT | E16: 45m 00s 03f | L16: HDR / SDR
B17: PART | E17: 01 | L17: COLOUR SPACE
B18: LANGUAGE | E18: Italian / English / French | L18: NITS PEAK
B19: NUMBER OF AD BREAKS | E19: Seamless | L19: MEDIUM/FORMAT
B20: ASPECT RATIO | E20: 2.39:1 | L20: CHROMA SUBSAMPLING
B21: DELIVERABLE | E21: Production Master UHD SDR
B22: PROD # | E22: N/A | L22: FIELD ORDER
B23: VENDOR | L23: VIDEO BIT DEPTH
B24: MO NUMBER | L24: VIDEO BIT RATE
B25: PSE CHECK | E25: N/A | L25: FILE SIZE
B26: VIDEO GAMUT | E26: PASS | L26: FIRST LINE
B27: LUMINANCE PEAK | E27: 100% | L27: LAST LINE
B28: FULL SUBTITLES | E28: No | L28: PIXEL ASPECT RATIO
B29: SUBTITLED SECTIONS | E29: No | L29: AUDIO CODEC/FORMAT
B30: LOUDNESS | E30: PASS | L30: AUDIO BIT RATE
B31: TRIM PASSES | E31: N/A | L31: AUDIO BIT DEPTH
L32: SAMPLE FREQUENCY
G33: PROGRAMME LAYOUT
B35: DESCRIPTION | I35: START TC | L35: END TC | O35: DUR
B37: Feature | I37: 0 | L37: 450003 | O37: 450003
G39: AUDIO SPECIFICATIONS
B41: CHANNEL | D41: DESCRIPTION | H41: LINE-UP TONE | J41: PEAK | K41: LOUDNESS (DIAL. GATED) | M41: LOUDNESS INTEGRATED | O41: STEREO | P41: FULL/SPOT CHECK
B42: CH1 | D42: 5.1 Mix Left | H42: N/A | J42: -2.48 | K42: -28.17 LUFS | M42: -22.41 LUFS | O42: OK | P42: FULL
B43: CH2 | D43: 5.1 Mix Right | H43: N/A | J43: -2.34 | K43: -28.17 LUFS | M43: -22.41 LUFS | O43: OK | P43: FULL
B44: CH3 | D44: 5.1 Mix Centre | H44: N/A | J44: -2.11 | K44: -28.17 LUFS | M44: -22.41 LUFS | O44: - | P44: FULL
B45: CH4 | D45: 5.1 Mix LFE | H45: N/A | J45: -3.01 | K45: -28.17 LUFS | M45: -22.41 LUFS | O45: - | P45: FULL
B46: CH5 | D46: 5.1 Mix Left Surround | H46: N/A | J46: -5.41 | K46: -28.17 LUFS | M46: -22.41 LUFS | O46: OK | P46: FULL
B47: CH6 | D47: 5.1 Mix Right Surround | H47: N/A | J47: -5.24 | K47: -28.17 LUFS | M47: -22.41 LUFS | O47: OK | P47: FULL
...

Sheet VIDEO ERRORS
D2: MASTER QC-A REPORT | H2: =OVERVIEW!O2 -> FAIL
B4: PRODUCTION COMPANY | D4: =OVERVIEW!E5 | G4: QC #
B5: TITLE | D5: =OVERVIEW!E6 | G5: PASS/FAIL | H5: =H2 -> FAIL
B6: EPISODE | D6: =OVERVIEW!E7 | G6: DATE | H6: =OVERVIEW!O7 -> 45403
B7: ELEMENT | D7: =OVERVIEW!E8 | G7: QC Operator | H7: =OVERVIEW!O8
B8: FILE NAME | D8: =OVERVIEW!E9 | G8: PAGE | H8: 2/5
B9: VIDEO ERROR LOG
B11: Grading Scale: FYI-Observations 1-Negligible 2-Needs Review 3-Severe 4-Stop Down (Automatic Fail)
B13: TC IN | C13: TC OUT | D13: DESCRIPTION | E13: SECTOR | F13: V/A/P/F | G13: GRADE | H13: RESPONSE
F14: Video
F15: Video
F16: Video
F17: Video
F18: Video
F19: Video
F20: Video
F21: Video
F22: Video
F23: Video
F24: Video
F25: Video
... F194: Video

Sheet AUDIO ERRORS
D2: MASTER QC-A REPORT | F2: =OVERVIEW!O2 -> FAIL
B4: PRODUCTION COMPANY | D4: =OVERVIEW!E5 | E4: QC #
B5: TITLE | E5: PASS/FAIL | F5: =F2 -> FAIL
B6: EPISODE | D6: =OVERVIEW!E7 | E6: DATE | F6: =OVERVIEW!O7 -> 45403
B7: ELEMENT | D7: =OVERVIEW!E8 | E7: QC Operator | F7: =OVERVIEW!O8
B8: FILE NAME | D8: =OVERVIEW!E9 | E8: PAGE | F8: 3/5
B9: AUDIO ERROR LOG
B11: 3 point scale: 1-Minor 2-Noticeable/Slightly annoying 3-Fault
B13: TC IN | C13: TC OUT | D13: DESCRIPTION | E13: GRADE | F13: RESPONSE

Sheet IN-SCENE TEXT LOG
D2: MASTER QC-A REPORT | F2: =OVERVIEW!O2 -> FAIL
B4: PRODUCTION COMPANY | D4: =OVERVIEW!E5 | E4: QC #
B5: TITLE | E5: PASS/FAIL | F5: =F2 -> FAIL
B6: EPISODE | D6: =OVERVIEW!E7 | E6: DATE | F6: =OVERVIEW!O7 -> 45403
B7: ELEMENT | D7: =OVERVIEW!E8 | E7: QC Operator | F7: =OVERVIEW!O8
B8: FILE NAME | D8: =OVERVIEW!E9 | E8: PAGE | F8: 4/5
B9: TEXT LOG
B12: TC IN | C12: TC OUT | D12: DESCRIPTION | E12: TYPE | F12: TEXTLESS REQ.

Sheet RECOMMENDATIONS
D2: MASTER QC-A REPORT | L2: =OVERVIEW!O2 -> FAIL
B4: PRODUCTION COMPANY | D4: =OVERVIEW!E5 | K4: QC #
B5: TITLE | K5: PASS/FAIL | L5: =L2 -> FAIL
B6: EPISODE | D6: =OVERVIEW!E7 | K6: DATE | L6: =OVERVIEW!O7 -> 45403
B7: ELEMENT | D7: =OVERVIEW!E8 | K7: QC Operator | L7: =OVERVIEW!O8
B8: FILE NAME | D8: =OVERVIEW!E9 | K8: PAGE | L8: 5/5
D12: RECOMMENDATIONS
B15: DETAIL | L15: MATERIAL REQUIRED TO FIX?

Sheet hideme
A1: CLOCK / SLATE | B1: TEXTLESS ELEMENTS | C1: VIDEO LEGAL | D1: PSE CHECK | E1: FULL SUBTITLES | F1: SUBTITLED | G1: CONTAINER | H1: CODEC | I1: RESOLUTION | J1: FRAME RATE | K1: HDR / SDR | L1: COLOUR SPACE | M1: CHROMA SUBSAMPLING | N1: FIELD ORDER | O1: ASPECT RATIO | P1: PIXEL ASPECT RATIO | Q1: R128 COMPIANT | R1: AUDIO CODEC | S1: AUDIO BIT DEPTH | T1: SAMPLE FREQUENCY
A2: Clock | B2: Yes | C2: Yes | D2: Pass | E2: Eng | F2: Eng | G2: .mov | H2: ProRes 422 (HQ) | I2: 1920 x 1080 | J2: 23.976 fps | K2: HDR - PQ | L2: BT.709 | M2: 4:2:2 | N2: Progressive | O2: 1.77:1 (16x9) | P2: 1:1 | Q2: Yes | R2: PCM - Little Endian | S2: 16 Bit | T2: 48 kHz
A3: Slate | B3: No | C3: No | D3: Fail | E3: Fre | F3: Fre | G3: .mxf | H3: XDCAM HD | I3: 3840 x 2160 | J3: 24 fps | K3: HDR - HLG | L3: BT.2020 | M3: 4:4:4 | N3: Interlaced UFF | O3: 1.778:1 | Q3: No | R3: PCM - Big Endian | S3: 24 Bit | T3: 96 kHz
A4: None | B4: Partial | C4: N/A | D4: N/A | E4: Ger | F4: Ger | G4: IMF | H4: AVC Intra | J4: 25 fps | K4: HDR | L4: P3 | N4: Interlaced LFF | O4: 1.85:1 | Q4: N/A
E5: Ita | F5: Ita | H5: DNxHR | J5: 29.97 fps DF | K5: SDR | O5: 1.89:1
J6: 29.97 fps NDF | K6: N/A | O6: 2.0:1
J7: 50 fps | O7: 2.2:1
J8: 60 fps | O8: 2.35:1
O9: 2.39:1
O10: 1.33:1 (4x3)
A12: SECTOR | B12: VIDEO GRADE | C12: AUDIO GRADE | D12: TEXTLESS PRESENT | F12: MATERIAL REQUIRED TO FIX
A13: U-L | B13: 1 | C13: 1 | D13: Yes | F13: Yes
A14: U-C | B14: 2 | C14: 2 | D14: No | F14: No
A15: U-R | B15: 3 | C15: 3 | D15: Incomplete | F15: Yes (or fixable in-house)
A16: M-L | B16: FYI | C16: FYI | D16: N/A
A17: M-C
A18: M-R
A19: L-L
A20: L-C
A21: L-R
